Workbook

Sheet Ponderaciones
B2: Bloque | C2: Porcentaje | D2: Fracción
B3: A | C3: 85 | D3: =C3/100 -> 0.85
B4: B | C4: 15 | D4: =C4/100 -> 0.15
B6: Aspecto a evaluar | C6: Porcentaje | D6: Fracción
B7: Cuaderno | C7: 20 | D7: =C7/100 -> 0.2
B8: Apreciativa | C8: 15 | D8: =C8/100 -> 0.15
B9: Quiz | C9: 25 | D9: =C9/100 -> 0.25
B10: Informes | C10: 40 | D10: =C10/100 -> 0.4

Sheet Cuaderno
B2: Sección | C2: Ponderación
B3: Fecha, número y título | C3: 1
B4: Objetivo general | C4: 1
B5: Objetivos específicos | C5: 1
B6: Marco teórico | C6: 5
B7: Met. exp. - Esquemas | C7: 3
B8: Met. exp. - Cálculos | C8: 2
B9: Met. exp. - Toxicología | C9: 1
B10: Resultados y presentación | C10: 4
B11: Observaciones | C11: 2
B12: Total | C12: =SUM(C3:C11) -> 20
C14: Semana
C15: 1 | D15: 2 | E15: 3 | F15: 4 | G15: 5 | H15: 6 | I15: 7 | J15: 8 | K15: 9 | L15: 10
B16: AGUSTIN ANDRADE | C16: 16.5 | D16: 19.75 | E16: 19 | F16: 16.75 | G16: 0 | H16: 0 | I16: 0 | J16: 0 | K16: 0 | L16: 0
B17: MAURICIO LEAL | C17: 14.75 | D17: 17.75 | E17: 19.75 | F17: 16.75 | G17: 0 | H17: 0 | I17: 0 | J17: 0 | K17: 0 | L17: 0
B18: MARIA DANIELA MEDINA | C18: 19.5 | D18: 19.75 | E18: 19.75 | F18: 20 | G18: 0 | H18: 0 | I18: 0 | J18: 0 | K18: 0 | L18: 0
B19: LUIS RIOS | C19: 19.25 | D19: 0 | E19: 19.75 | F19: 19 | G19: 0 | H19: 0 | I19: 0 | J19: 0 | K19: 0 | L19: 0
B20: DANIELA RONDON | C20: 19.5 | D20: 0 | E20: 20 | F20: 20 | G20: 0 | H20: 0 | I20: 0 | J20: 0 | K20: 0 | L20: 0

Sheet Gestión del laboratorio
C2: Semana
C3: 1 | D3: 2 | E3: 3 | F3: 4 | G3: 5 | H3: 6 | I3: 7 | J3: 8 | K3: 9 | L3: 10
B4: AGUSTIN ANDRADE | C4: 20 | D4: 20 | E4: 20 | F4: 10 | G4: 20 | H4: 0 | I4: 0 | J4: 0 | K4: 0 | L4: 0
B5: MAURICIO LEAL | C5: 15 | D5: 17 | E5: 20 | F5: 20 | G5: 17 | H5: 0 | I5: 0 | J5: 0 | K5: 0 | L5: 0
B6: MARIA DANIELA MEDINA | C6: 15 | D6: 20 | E6: 15 | F6: 10 | G6: 17 | H6: 0 | I6: 0 | J6: 0 | K6: 0 | L6: 0
B7: LUIS RIOS | C7: 20 | D7: 20 | E7: 20 | F7: 10 | G7: 17 | H7: 0 | I7: 0 | J7: 0 | K7: 0 | L7: 0
B8: DANIELA RONDON | C8: 20 | D8: 20 | E8: 15 | F8: 20 | G8: 20 | H8: 0 | I8: 0 | J8: 0 | K8: 0 | L8: 0

Sheet Quiz
C2: Semana
C3: 20.05.26 | D3: 27.06.26 | E3: 03.06.26 | F3: 11.06.26 | G3: 17.06.26
C4: 1 | D4: 2 | E4: 3 | F4: 4 | G4: 5 | H4: 6 | I4: 7 | J4: 8 | K4: 9 | L4: 10
B5: AGUSTIN ANDRADE | C5: 18 | D5: 20 | E5: 17 | F5: 17.5 | G5: 13 | H5: 0 | I5: 0 | J5: 0 | K5: 0 | L5: 0
B6: MAURICIO LEAL | C6: 16.5 | D6: 18.5 | E6: 17 | F6: 20 | G6: 18.5 | H6: 0 | I6: 0 | J6: 0 | K6: 0 | L6: 0
B7: MARIA DANIELA MEDINA | C7: 14 | D7: 11.5 | E7: 14 | F7: 11.5 | G7: 13 | H7: 0 | I7: 0 | J7: 0 | K7: 0 | L7: 0
B8: LUIS RIOS | C8: 18.5 | D8: 19 | E8: 20 | F8: 20 | G8: 17 | H8: 0 | I8: 0 | J8: 0 | K8: 0 | L8: 0
B9: DANIELA RONDON | C9: 17 | D9: 13.5 | E9: 19 | F9: 17 | G9: 17.5 | H9: 0 | I9: 0 | J9: 0 | K9: 0 | L9: 0

Sheet Informes por bloque
B2: Sección | C2: Ponderación
B3: Resumen | C3: 2
B4: Introducción | C4: 1
B5: Objetivos | C5: 2
B6: Metodología experimental | C6: 1
B7: Resultados y discusiones | C7: 10
B8: Conclusiones | C8: 3
B9: Anexos | C9: 1
B10: Total | C10: =SUM(C3:C9) -> 20
B12: Informe - Bloque A
B13: Estudiante | C13: Título y resumen | D13: Introducción | E13: Objetivos | F13: Metodología experimental | G13: Resultados y discusiones | H13: Conclusiones | I13: Anexos
B14: AGUSTIN ANDRADE | C14: 1 | D14: 0.6 | E14: 1.75 | F14: 0.75 | G14: 5 | H14: 2 | I14: 0.5
B15: MAURICIO LEAL | C15: 1.4 | D15: 0.5 | E15: 1.75 | F15: 1 | G15: 7 | H15: 3 | I15: 1
B16: MARIA DANIELA MEDINA | C16: 1 | D16: 0.6 | E16: 1.75 | F16: 0.75 | G16: 5 | H16: 2 | I16: 0.5
B17: LUIS RIOS | C17: 1.4 | D17: 0.5 | E17: 1.75 | F17: 1 | G17: 7 | H17: 3 | I17: 1
B18: DANIELA RONDON | C18: 2 | D18: 1 | E18: 2 | F18: 1 | G18: 10 | H18: 3 | I18: 1
B21: Informe - Bloque B
B22: Estudiante | C22: Título y resumen | D22: Introducción | E22: Objetivos | F22: Metodología experimental | G22: Resultados y discusiones | H22: Conclusiones | I22: Anexos
B23: AGUSTIN ANDRADE
B24: MAURICIO LEAL
B25: MARIA DANIELA MEDINA
B26: LUIS RIOS
B27: DANIELA RONDON
B30: Informe - Bloque C
B31: Estudiante | C31: Título y resumen | D31: Introducción | E31: Objetivos | F31: Metodología experimental | G31: Resultados y discusiones | H31: Conclusiones | I31: Anexos
B32: AGUSTIN ANDRADE
B33: MAURICIO LEAL
B34: MARIA DANIELA MEDINA
B35: LUIS RIOS
B36: DANIELA RONDON
B39: Informe - Bloque D
B40: Estudiante | C40: Título y resumen | D40: Introducción | E40: Objetivos | F40: Metodología experimental | G40: Resultados y discusiones | H40: Conclusiones | I40: Anexos
B41: AGUSTIN ANDRADE
B42: MAURICIO LEAL
B43: MARIA DANIELA MEDINA
B44: LUIS RIOS
B45: DANIELA RONDON
B48: Informe - Bloque E
B49: Estudiante | C49: Título y resumen | D49: Introducción | E49: Objetivos | F49: Metodología experimental | G49: Resultados y discusiones | H49: Conclusiones | I49: Anexos
B50: AGUSTIN ANDRADE
...

Sheet Notas informes
C2: Informes
C3: A | D3: B | E3: C | F3: D | G3: E
B4: AGUSTIN ANDRADE | C4: =SUM('Informes por bloque'!C14:I14) -> 11.6 | D4: =SUM('Informes por bloque'!C23:I23) -> 0 | E4: =SUM('Informes por bloque'!C32:I32) -> 0 | F4: =SUM('Informes por bloque'!C41:I41) -> 0 | G4: =SUM('Informes por bloque'!C50:I50) -> 0
B5: MAURICIO LEAL | C5: =SUM('Informes por bloque'!C15:I15) -> 15.65 | D5: =SUM('Informes por bloque'!C24:I24) -> 0 | E5: =SUM('Informes por bloque'!C33:I33) -> 0 | F5: =SUM('Informes por bloque'!C42:I42) -> 0 | G5: =SUM('Informes por bloque'!C51:I51) -> 0
B6: MARIA DANIELA MEDINA | C6: =SUM('Informes por bloque'!C16:I16) -> 11.6 | D6: =SUM('Informes por bloque'!C25:I25) -> 0 | E6: =SUM('Informes por bloque'!C34:I34) -> 0 | F6: =SUM('Informes por bloque'!C43:I43) -> 0 | G6: =SUM('Informes por bloque'!C52:I52) -> 0
B7: LUIS RIOS | C7: =SUM('Informes por bloque'!C17:I17) -> 15.65 | D7: =SUM('Informes por bloque'!C26:I26) -> 0 | E7: =SUM('Informes por bloque'!C35:I35) -> 0 | F7: =SUM('Informes por bloque'!C44:I44) -> 0 | G7: =SUM('Informes por bloque'!C53:I53) -> 0
B8: DANIELA RONDON | C8: =SUM('Informes por bloque'!C18:I18) -> 20 | D8: =SUM('Informes por bloque'!C27:I27) -> 0 | E8: =SUM('Informes por bloque'!C36:I36) -> 0 | F8: =SUM('Informes por bloque'!C45:I45) -> 0 | G8: =SUM('Informes por bloque'!C54:I54) -> 0

Sheet Acumulado Bloque A
D2: Cuaderno | E2: Gestión lababoratorio | F2: Quiz | G2: Informe | H2: Acumulado Bloque A | I2: Bloque A (85%)
B3: 28233037 | C3: AGUSTIN ANDRADE | D3: =AVERAGE(Cuaderno!C16:L16)*Ponderaciones!$D$7 -> 1.44 | E3: =AVERAGE('Gestión del laboratorio'!C4:L4)*Ponderaciones!$D$8 -> 1.35 | F3: =AVERAGE(Quiz!C5:L5)*Ponderaciones!$D$9 -> 2.1375 | G3: =AVERAGE('Notas informes'!C4:G4)*Ponderaciones!$D$10 -> 0.928 | H3: =SUM(D3:G3) -> 5.8555 | I3: =H3*Ponderaciones!$D$3 -> 4.977175
B4: 27111264 | C4: MAURICIO LEAL | D4: =AVERAGE(Cuaderno!C17:L17)*Ponderaciones!$D$7 -> 1.38 | E4: =AVERAGE('Gestión del laboratorio'!C5:L5)*Ponderaciones!$D$8 -> 1.335 | F4: =AVERAGE(Quiz!C6:L6)*Ponderaciones!$D$9 -> 2.2625 | G4: =AVERAGE('Notas informes'!C5:G5)*Ponderaciones!$D$10 -> 1.252 | H4: =SUM(D4:G4) -> 6.2295 | I4: =H4*Ponderaciones!$D$3 -> 5.295075
B5: 21073829 | C5: MARIA DANIELA MEDINA | D5: =AVERAGE(Cuaderno!C18:L18)*Ponderaciones!$D$7 -> 1.58 | E5: =AVERAGE('Gestión del laboratorio'!C6:L6)*Ponderaciones!$D$8 -> 1.155 | F5: =AVERAGE(Quiz!C7:L7)*Ponderaciones!$D$9 -> 1.6 | G5: =AVERAGE('Notas informes'!C6:G6)*Ponderaciones!$D$10 -> 0.928 | H5: =SUM(D5:G5) -> 5.263 | I5: =H5*Ponderaciones!$D$3 -> 4.47355
B6: 29529906 | C6: LUIS RIOS | D6: =AVERAGE(Cuaderno!C19:L19)*Ponderaciones!$D$7 -> 1.16 | E6: =AVERAGE('Gestión del laboratorio'!C7:L7)*Ponderaciones!$D$8 -> 1.305 | F6: =AVERAGE(Quiz!C8:L8)*Ponderaciones!$D$9 -> 2.3625 | G6: =AVERAGE('Notas informes'!C7:G7)*Ponderaciones!$D$10 -> 1.252 | H6: =SUM(D6:G6) -> 6.0795 | I6: =H6*Ponderaciones!$D$3 -> 5.167575
B7: 29501138 | C7: DANIELA RONDON | D7: =AVERAGE(Cuaderno!C20:L20)*Ponderaciones!$D$7 -> 1.19 | E7: =AVERAGE('Gestión del laboratorio'!C8:L8)*Ponderaciones!$D$8 -> 1.425 | F7: =AVERAGE(Quiz!C9:L9)*Ponderaciones!$D$9 -> 2.1 | G7: =AVERAGE('Notas informes'!C8:G8)*Ponderaciones!$D$10 -> 1.6 | H7: =SUM(D7:G7) -> 6.315 | I7: =H7*Ponderaciones!$D$3 -> 5.36775

Sheet Seminario - Bloque B
C2: Calificación | D2: Bloque B (15%)
B3: AGUSTIN ANDRADE | C3: 0 | D3: =C3*Ponderaciones!$D$4 -> 0
B4: MAURICIO LEAL | C4: 0 | D4: =C4*Ponderaciones!$D$4 -> 0
B5: MARIA DANIELA MEDINA | C5: 0 | D5: =C5*Ponderaciones!$D$4 -> 0
B6: LUIS RIOS | C6: 0 | D6: =C6*Ponderaciones!$D$4 -> 0
B7: DANIELA RONDON | C7: 0 | D7: =C7*Ponderaciones!$D$4 -> 0

Sheet Acumulado global
D2: Bloque A (85%) | E2: Bloque B (15%) | F2: Nota acumulada | G2: Nota Final
B3: 28233037 | C3: AGUSTIN ANDRADE | D3: ='Acumulado Bloque A'!I3 -> 4.977175 | E3: ='Seminario - Bloque B'!D3 -> 0 | F3: =SUM(D3:E3) -> 4.977175 | G3: =F3 -> 4.977175
B4: 27111264 | C4: MAURICIO LEAL | D4: ='Acumulado Bloque A'!I4 -> 5.295075 | E4: ='Seminario - Bloque B'!D4 -> 0 | F4: =SUM(D4:E4) -> 5.295075 | G4: =F4 -> 5.295075
B5: 21073829 | C5: MARIA DANIELA MEDINA | D5: ='Acumulado Bloque A'!I5 -> 4.47355 | E5: ='Seminario - Bloque B'!D5 -> 0 | F5: =SUM(D5:E5) -> 4.47355 | G5: =F5 -> 4.47355
B6: 29529906 | C6: LUIS RIOS | D6: ='Acumulado Bloque A'!I6 -> 5.167575 | E6: ='Seminario - Bloque B'!D6 -> 0 | F6: =SUM(D6:E6) -> 5.167575 | G6: =F6 -> 5.167575
B7: 29501138 | C7: DANIELA RONDON | D7: ='Acumulado Bloque A'!I7 -> 5.36775 | E7: ='Seminario - Bloque B'!D7 -> 0 | F7: =SUM(D7:E7) -> 5.36775 | G7: =F7 -> 5.36775
